<robot name = "diff_drive">
    
    <link name = "base_link">
        <visual name = "base_visual">
            <origin xyz = "0 0 0" rpy = "0 0 0"/>
            <geometry>
                <box size = "0.6 0.4 0.1"/>
            </geometry>
            <material name = "dark_grey">
                <color rgba = "0.2 0.2 0.2 1.0"/>
            </material>
        </visual>
    </link>

    <link name = "left_wheel">
        <visual name = "left_wheel_visual">
            <origin xyz = "0 0 0" rpy = "0 0 0"/>
            <geometry>
                <cylinder radius = "0.1" length = "0.04"/>
            </geometry>
            <material name = "red">
                <color rgba = "1 0.2 0.2 1.0"/>
            </material>
        </visual>
    </link>


    <joint name = "left_wheel_joint" type = "continuous">
        <origin xyz="-0.1 0.22 0" rpy="0.0 -1.57 -1.57"/>
        <parent link="base_link"/>
        <child link="left_wheel"/>
        <axis xyz = "0 0 1"/>
    </joint>
    

    <link name = "right_wheel">
        <visual name = "right_wheel_visual">
            <origin xyz = "0 0 0" rpy = "0 0 0"/>
            <geometry>
                <cylinder radius = "0.1" length = "0.04"/>
            </geometry>
            <material name = "red">
                <color rgba = "1 0.2 0.2 1.0"/>
            </material>
        </visual>
    </link>


    <joint name = "right_wheel_joint" type = "continuous">
        <origin xyz="-0.1 -0.22 0" rpy="0 -1.57 -1.57"/>
        <parent link="base_link"/>
        <child link="right_wheel"/>
        <axis xyz = "0 0 1"/>
    </joint>




    <link name = "cluster_support">
        <visual name = "cluster_support_visual">
            <origin xyz = "0 0 0" rpy = "0 0 0"/>
            <geometry>
                <cylinder radius="0.02" length="0.1"/>
            </geometry>
            <material name = "green">
                <color rgba = "0.2 1.0 0.2 1.0"/>
            </material>
        </visual>
    </link>


    <joint name = "cluster_support_joint" type = "continuous">
        <origin xyz="0.32 0 0" rpy="0 0 0"/>
        <parent link="base_link"/>
        <child link="cluster_support"/>
        <axis xyz = "0 0 1"/>
    </joint>



    <link name = "cluster_wheel">
        <visual name = "roller_wheel_visual">
            <origin xyz = "0 0 0" rpy = "0 0 0"/>
            <geometry>
                <cylinder radius = "0.025" length = "0.01"/>
            </geometry>
            <material name = "blue">
                <color rgba = "0.2 0.2 1.0 1.0"/>
            </material>
        </visual>
    </link>


    <joint name = "cluster_wheel_joint" type = "continuous">
        <origin xyz="0 0 -0.075" rpy="0 -1.57 -1.57"/>
        <parent link="cluster_support"/>
        <child link="cluster_wheel"/>
        <axis xyz = "0 0 1"/>
    </joint>



</robot>